try {
    let a = noExiste()
} catch (error) {
   alert('No existe') 
}

// con throw disparamos excepciones
// throw 0, throw 1, throw 2, throw 3--> esto es para el ejercicio del factorial, por lo que lanzarias esos valores
